<?xml version='1.0' ?>

<robot name="puma560">

    <material name="red">
        <color rgba="1 0 0 1"/>
    </material>
    <material name="orange">
        <color rgba="1 0.2 0 1"/>
    </material>
    <material name="yellow">
        <color rgba="1 1 0 1"/>
    </material>
    <material name="green">
        <color rgba="0 1 0 1"/>
    </material>
    <material name="blue">
        <color rgba="0 0 1 1"/>
    </material>
    <material name="black">
        <color rgba="0 0 0 1"/>
    </material>
    <material name="purple">
        <color rgba="0.4 0 1 1"/>
    </material>
    
    <link name="world"/>

    <joint name="joint_world" type="fixed">
        <parent link="world"/>
        <child link="base"/>
        <origin rpy="0 0 0" xyz="0 0 0"/>
    </joint>

    <link name="base">
        <visual>
            <origin xyz="0 0 0" rpy="0 0 0" />
            <geometry>
		    <mesh filename="package://puma560/meshes/axis0.stl"/>
            </geometry>
            <material name="red"/>
        </visual>
    </link>

    <joint name="joint01" type="revolute">
        <origin xyz="0 0 0.239" rpy="0 0 0"/>
        <parent link="base"/>
        <child link="link1"/>
        <axis xyz='0 0 1'/>
        <calibration rising="0.0"/>
        <dynamics damping="0.0" friction="0.0"/>
        <limit effort="30" velocity="1.0" lower="-3.14" upper="3.14" />
        <safety_controller k_velocity="10" k_position="15" soft_lower_limit="-3.14" soft_upper_limit="3.14" />
    </joint>
    
    <link name="link1">
        <visual>
            <origin xyz="0 0 0" rpy="0 0 0" />
            <geometry>
		    <mesh filename="package://puma560/meshes/axis1.stl"/>
            </geometry>
            <material name="orange"/>
        </visual>
    </link>

    <joint name="joint12" type="revolute">
        <origin xyz="0.08 0 0.0033" rpy="-1.5707963268 0 0"/>
        <parent link="link1"/>
        <child link="link2"/>
        <axis xyz='0 0 1'/>
        <calibration rising="0.0"/>
        <dynamics damping="0.0" friction="0.0"/>
        <limit effort="30" velocity="1.0" lower="-2.0043950955" upper="1.5707963268" />
        <safety_controller k_velocity="10" k_position="15" soft_lower_limit="-3.14" soft_upper_limit="3.14" />
    </joint>

    <link name="link2">
        <visual>
            <origin xyz="0 0 0" rpy="0 0 0" />
            <geometry>
		    <mesh filename="package://puma560/meshes/axis2.stl"/>
            </geometry>
            <material name="yellow"/>
        </visual>
    </link>


    <joint name="joint23" type="revolute">
        <origin xyz="0.1156 0 -0.002" rpy="0 0 0"/>
        <parent link="link2"/>
        <child link="link3"/>
        <axis xyz='0 0 1'/>
        <calibration rising="0.0"/>
        <dynamics damping="0.0" friction="0.0"/>
        <limit effort="30" velocity="1.0" lower="-0.3141592653" upper="3.4557519188" />
        <safety_controller k_velocity="10" k_position="15" soft_lower_limit="-3.14" soft_upper_limit="3.14" />
    </joint>

    <link name="link3">
        <visual>
            <origin xyz="0 0 0" rpy="0 0 0" />
            <geometry>
		    <mesh filename="package://puma560/meshes/axis3.stl"/>
            </geometry>
            <material name="green"/>
        </visual>
    </link>


    <joint name="joint34" type="revolute">
        <origin xyz="-0.01234 -0.148 0.00075" rpy="0 1.5707963268 -1.5707963268"/>
        <parent link="link3"/>
        <child link="link4"/>
        <axis xyz='0 0 1'/>
        <calibration rising="0.0"/>
        <dynamics damping="0.0" friction="0.0"/>
        <limit effort="30" velocity="1.0" lower="-3.14" upper="3.14" />
        <safety_controller k_velocity="10" k_position="15" soft_lower_limit="-3.14" soft_upper_limit="3.14" />
    </joint>

    <link name="link4">
        <visual>
            <origin xyz="0 0 0" rpy="0 0 0" />
            <geometry>
		    <mesh filename="package://puma560/meshes/axis4.stl"/>
            </geometry>
            <material name="blue"/>
        </visual>
    </link>


    <joint name="joint45" type="revolute">
        <origin xyz="-0.0002 -0.0488 0.0602" rpy="-1.5707963268 0 0"/>
        <parent link="link4"/>
        <child link="link5"/>
        <axis xyz='0 0 1'/>
        <calibration rising="0.0"/>
        <dynamics damping="0.0" friction="0.0"/>
        <limit effort="30" velocity="1.0" lower="-2.0561944901" upper="2.0561944901" />
        <safety_controller k_velocity="10" k_position="15" soft_lower_limit="-3.14" soft_upper_limit="3.14" />
    </joint>

    <link name="link5">
        <visual>
            <origin xyz="0 0 0" rpy="0 0 0" />
            <geometry>
		    <mesh filename="package://puma560/meshes/axis5.stl"/>
            </geometry>
            <material name="black"/>
        </visual>
    </link>

    <joint name="joint56" type="revolute">
        <origin xyz="0 -0.06422 0.04994" rpy="1.5707963268 -1.5707963268 0"/>
        <parent link="link5"/>
        <child link="link6"/>
        <axis xyz='0 0 1'/>
        <calibration rising="0.0"/>
        <dynamics damping="0.0" friction="0.0"/>
        <limit effort="30" velocity="1.0" lower="-3.14" upper="3.14" />
        <safety_controller k_velocity="10" k_position="15" soft_lower_limit="-3.14" soft_upper_limit="3.14" />
    </joint>

    <link name="link6">
        <visual>
            <origin xyz="0 0 0" rpy="0 0 0" />
            <geometry>
		    <mesh filename="package://puma560/meshes/axis6.stl"/>
            </geometry>
            <material name="purple"/>
        </visual>
    </link>

</robot>
